WARNING:werkzeug: * Debugger is active!
INFO:werkzeug: * Debugger PIN: 801-066-297
INFO:root:Client connected
ERROR:root:frame does not detect a proper face
INFO:root:Name: captured_image_20231127120947
INFO:root:Name: captured_image_20231127120947
INFO:root:Name: captured_image_20231127120947
INFO:root:Name: captured_image_20231127120947
INFO:root:Name: captured_image_20231127120947
INFO:root:Name: captured_image_20231127120947
INFO:root:Name: captured_image_20231127120947
INFO:root:Name: captured_image_20231127120947
INFO:root:Name: captured_image_20231127120947
INFO:root:Name: captured_image_20231127120947
ERROR:root:frame does not detect a proper face
INFO:root:Name: captured_image_20231127120947
INFO:root:Name: captured_image_20231127120947
INFO:root:Name: captured_image_20231127120947
INFO:werkzeug: * Detected change in 'C:\\Users\\Admin\\PycharmProjects\\Facedetection_matched_ML\\spoofing_face_match_application.py', reloading
INFO:werkzeug: * Restarting with stat
WARNING:werkzeug: * Debugger is active!
INFO:werkzeug: * Debugger PIN: 801-066-297
INFO:root:Client connected
ERROR:root:frame does not detect a proper face
INFO:root:Name: captured_image_20231127120947
INFO:root:Name: captured_image_20231127120947
INFO:root:Name: captured_image_20231127120947
INFO:root:Name: captured_image_20231127120947
INFO:root:Name: captured_image_20231127120947
INFO:root:Name: captured_image_20231127120947
INFO:werkzeug: * Restarting with stat
WARNING:werkzeug: * Debugger is active!
INFO:werkzeug: * Debugger PIN: 801-066-297
INFO:root:Client connected
ERROR:root:frame does not detect a proper face
ERROR:root:Error: OpenCV(4.6.0) D:\a\opencv-python\opencv-python\opencv\modules\dnn\src\caffe\caffe_io.cpp:1126: error: (-2:Unspecified error) FAILED: fs.is_open(). Can't open "C:\Users\Admin\PycharmProjects\Facedetection_matched_ML\src\..\resources\detection_model\deploy.prototxt" in function 'cv::dnn::ReadProtoFromTextFile'

ERROR:root:Error: OpenCV(4.6.0) D:\a\opencv-python\opencv-python\opencv\modules\dnn\src\caffe\caffe_io.cpp:1126: error: (-2:Unspecified error) FAILED: fs.is_open(). Can't open "C:\Users\Admin\PycharmProjects\Facedetection_matched_ML\src\..\resources\detection_model\deploy.prototxt" in function 'cv::dnn::ReadProtoFromTextFile'

ERROR:root:Error: OpenCV(4.6.0) D:\a\opencv-python\opencv-python\opencv\modules\dnn\src\caffe\caffe_io.cpp:1126: error: (-2:Unspecified error) FAILED: fs.is_open(). Can't open "C:\Users\Admin\PycharmProjects\Facedetection_matched_ML\src\..\resources\detection_model\deploy.prototxt" in function 'cv::dnn::ReadProtoFromTextFile'

ERROR:root:Error: OpenCV(4.6.0) D:\a\opencv-python\opencv-python\opencv\modules\dnn\src\caffe\caffe_io.cpp:1126: error: (-2:Unspecified error) FAILED: fs.is_open(). Can't open "C:\Users\Admin\PycharmProjects\Facedetection_matched_ML\src\..\resources\detection_model\deploy.prototxt" in function 'cv::dnn::ReadProtoFromTextFile'

ERROR:root:Error: OpenCV(4.6.0) D:\a\opencv-python\opencv-python\opencv\modules\dnn\src\caffe\caffe_io.cpp:1126: error: (-2:Unspecified error) FAILED: fs.is_open(). Can't open "C:\Users\Admin\PycharmProjects\Facedetection_matched_ML\src\..\resources\detection_model\deploy.prototxt" in function 'cv::dnn::ReadProtoFromTextFile'

ERROR:root:Error: OpenCV(4.6.0) D:\a\opencv-python\opencv-python\opencv\modules\dnn\src\caffe\caffe_io.cpp:1126: error: (-2:Unspecified error) FAILED: fs.is_open(). Can't open "C:\Users\Admin\PycharmProjects\Facedetection_matched_ML\src\..\resources\detection_model\deploy.prototxt" in function 'cv::dnn::ReadProtoFromTextFile'

ERROR:root:Error: OpenCV(4.6.0) D:\a\opencv-python\opencv-python\opencv\modules\dnn\src\caffe\caffe_io.cpp:1126: error: (-2:Unspecified error) FAILED: fs.is_open(). Can't open "C:\Users\Admin\PycharmProjects\Facedetection_matched_ML\src\..\resources\detection_model\deploy.prototxt" in function 'cv::dnn::ReadProtoFromTextFile'

ERROR:root:Error: OpenCV(4.6.0) D:\a\opencv-python\opencv-python\opencv\modules\dnn\src\caffe\caffe_io.cpp:1126: error: (-2:Unspecified error) FAILED: fs.is_open(). Can't open "C:\Users\Admin\PycharmProjects\Facedetection_matched_ML\src\..\resources\detection_model\deploy.prototxt" in function 'cv::dnn::ReadProtoFromTextFile'

ERROR:root:Error: OpenCV(4.6.0) D:\a\opencv-python\opencv-python\opencv\modules\dnn\src\caffe\caffe_io.cpp:1126: error: (-2:Unspecified error) FAILED: fs.is_open(). Can't open "C:\Users\Admin\PycharmProjects\Facedetection_matched_ML\src\..\resources\detection_model\deploy.prototxt" in function 'cv::dnn::ReadProtoFromTextFile'

ERROR:root:Error: OpenCV(4.6.0) D:\a\opencv-python\opencv-python\opencv\modules\dnn\src\caffe\caffe_io.cpp:1126: error: (-2:Unspecified error) FAILED: fs.is_open(). Can't open "C:\Users\Admin\PycharmProjects\Facedetection_matched_ML\src\..\resources\detection_model\deploy.prototxt" in function 'cv::dnn::ReadProtoFromTextFile'

ERROR:root:Error: OpenCV(4.6.0) D:\a\opencv-python\opencv-python\opencv\modules\dnn\src\caffe\caffe_io.cpp:1126: error: (-2:Unspecified error) FAILED: fs.is_open(). Can't open "C:\Users\Admin\PycharmProjects\Facedetection_matched_ML\src\..\resources\detection_model\deploy.prototxt" in function 'cv::dnn::ReadProtoFromTextFile'

ERROR:root:Error: OpenCV(4.6.0) D:\a\opencv-python\opencv-python\opencv\modules\dnn\src\caffe\caffe_io.cpp:1126: error: (-2:Unspecified error) FAILED: fs.is_open(). Can't open "C:\Users\Admin\PycharmProjects\Facedetection_matched_ML\src\..\resources\detection_model\deploy.prototxt" in function 'cv::dnn::ReadProtoFromTextFile'

ERROR:root:Error: OpenCV(4.6.0) D:\a\opencv-python\opencv-python\opencv\modules\dnn\src\caffe\caffe_io.cpp:1126: error: (-2:Unspecified error) FAILED: fs.is_open(). Can't open "C:\Users\Admin\PycharmProjects\Facedetection_matched_ML\src\..\resources\detection_model\deploy.prototxt" in function 'cv::dnn::ReadProtoFromTextFile'

ERROR:root:Error: OpenCV(4.6.0) D:\a\opencv-python\opencv-python\opencv\modules\dnn\src\caffe\caffe_io.cpp:1126: error: (-2:Unspecified error) FAILED: fs.is_open(). Can't open "C:\Users\Admin\PycharmProjects\Facedetection_matched_ML\src\..\resources\detection_model\deploy.prototxt" in function 'cv::dnn::ReadProtoFromTextFile'

ERROR:root:Error: OpenCV(4.6.0) D:\a\opencv-python\opencv-python\opencv\modules\dnn\src\caffe\caffe_io.cpp:1126: error: (-2:Unspecified error) FAILED: fs.is_open(). Can't open "C:\Users\Admin\PycharmProjects\Facedetection_matched_ML\src\..\resources\detection_model\deploy.prototxt" in function 'cv::dnn::ReadProtoFromTextFile'

ERROR:root:Error: OpenCV(4.6.0) D:\a\opencv-python\opencv-python\opencv\modules\dnn\src\caffe\caffe_io.cpp:1126: error: (-2:Unspecified error) FAILED: fs.is_open(). Can't open "C:\Users\Admin\PycharmProjects\Facedetection_matched_ML\src\..\resources\detection_model\deploy.prototxt" in function 'cv::dnn::ReadProtoFromTextFile'

ERROR:root:Error: OpenCV(4.6.0) D:\a\opencv-python\opencv-python\opencv\modules\dnn\src\caffe\caffe_io.cpp:1126: error: (-2:Unspecified error) FAILED: fs.is_open(). Can't open "C:\Users\Admin\PycharmProjects\Facedetection_matched_ML\src\..\resources\detection_model\deploy.prototxt" in function 'cv::dnn::ReadProtoFromTextFile'

ERROR:root:Error: OpenCV(4.6.0) D:\a\opencv-python\opencv-python\opencv\modules\dnn\src\caffe\caffe_io.cpp:1126: error: (-2:Unspecified error) FAILED: fs.is_open(). Can't open "C:\Users\Admin\PycharmProjects\Facedetection_matched_ML\src\..\resources\detection_model\deploy.prototxt" in function 'cv::dnn::ReadProtoFromTextFile'

ERROR:root:Error: OpenCV(4.6.0) D:\a\opencv-python\opencv-python\opencv\modules\dnn\src\caffe\caffe_io.cpp:1126: error: (-2:Unspecified error) FAILED: fs.is_open(). Can't open "C:\Users\Admin\PycharmProjects\Facedetection_matched_ML\src\..\resources\detection_model\deploy.prototxt" in function 'cv::dnn::ReadProtoFromTextFile'

ERROR:root:Error: OpenCV(4.6.0) D:\a\opencv-python\opencv-python\opencv\modules\dnn\src\caffe\caffe_io.cpp:1126: error: (-2:Unspecified error) FAILED: fs.is_open(). Can't open "C:\Users\Admin\PycharmProjects\Facedetection_matched_ML\src\..\resources\detection_model\deploy.prototxt" in function 'cv::dnn::ReadProtoFromTextFile'

ERROR:root:Error: OpenCV(4.6.0) D:\a\opencv-python\opencv-python\opencv\modules\dnn\src\caffe\caffe_io.cpp:1126: error: (-2:Unspecified error) FAILED: fs.is_open(). Can't open "C:\Users\Admin\PycharmProjects\Facedetection_matched_ML\src\..\resources\detection_model\deploy.prototxt" in function 'cv::dnn::ReadProtoFromTextFile'

ERROR:root:Error: OpenCV(4.6.0) D:\a\opencv-python\opencv-python\opencv\modules\dnn\src\caffe\caffe_io.cpp:1126: error: (-2:Unspecified error) FAILED: fs.is_open(). Can't open "C:\Users\Admin\PycharmProjects\Facedetection_matched_ML\src\..\resources\detection_model\deploy.prototxt" in function 'cv::dnn::ReadProtoFromTextFile'

ERROR:root:Error: OpenCV(4.6.0) D:\a\opencv-python\opencv-python\opencv\modules\dnn\src\caffe\caffe_io.cpp:1126: error: (-2:Unspecified error) FAILED: fs.is_open(). Can't open "C:\Users\Admin\PycharmProjects\Facedetection_matched_ML\src\..\resources\detection_model\deploy.prototxt" in function 'cv::dnn::ReadProtoFromTextFile'

ERROR:root:Error: OpenCV(4.6.0) D:\a\opencv-python\opencv-python\opencv\modules\dnn\src\caffe\caffe_io.cpp:1126: error: (-2:Unspecified error) FAILED: fs.is_open(). Can't open "C:\Users\Admin\PycharmProjects\Facedetection_matched_ML\src\..\resources\detection_model\deploy.prototxt" in function 'cv::dnn::ReadProtoFromTextFile'

ERROR:root:Error: OpenCV(4.6.0) D:\a\opencv-python\opencv-python\opencv\modules\dnn\src\caffe\caffe_io.cpp:1126: error: (-2:Unspecified error) FAILED: fs.is_open(). Can't open "C:\Users\Admin\PycharmProjects\Facedetection_matched_ML\src\..\resources\detection_model\deploy.prototxt" in function 'cv::dnn::ReadProtoFromTextFile'

ERROR:root:Error: OpenCV(4.6.0) D:\a\opencv-python\opencv-python\opencv\modules\dnn\src\caffe\caffe_io.cpp:1126: error: (-2:Unspecified error) FAILED: fs.is_open(). Can't open "C:\Users\Admin\PycharmProjects\Facedetection_matched_ML\src\..\resources\detection_model\deploy.prototxt" in function 'cv::dnn::ReadProtoFromTextFile'

ERROR:root:Error: OpenCV(4.6.0) D:\a\opencv-python\opencv-python\opencv\modules\dnn\src\caffe\caffe_io.cpp:1126: error: (-2:Unspecified error) FAILED: fs.is_open(). Can't open "C:\Users\Admin\PycharmProjects\Facedetection_matched_ML\src\..\resources\detection_model\deploy.prototxt" in function 'cv::dnn::ReadProtoFromTextFile'

ERROR:root:Error: OpenCV(4.6.0) D:\a\opencv-python\opencv-python\opencv\modules\dnn\src\caffe\caffe_io.cpp:1126: error: (-2:Unspecified error) FAILED: fs.is_open(). Can't open "C:\Users\Admin\PycharmProjects\Facedetection_matched_ML\src\..\resources\detection_model\deploy.prototxt" in function 'cv::dnn::ReadProtoFromTextFile'

ERROR:root:Error: OpenCV(4.6.0) D:\a\opencv-python\opencv-python\opencv\modules\dnn\src\caffe\caffe_io.cpp:1126: error: (-2:Unspecified error) FAILED: fs.is_open(). Can't open "C:\Users\Admin\PycharmProjects\Facedetection_matched_ML\src\..\resources\detection_model\deploy.prototxt" in function 'cv::dnn::ReadProtoFromTextFile'

ERROR:root:Error: OpenCV(4.6.0) D:\a\opencv-python\opencv-python\opencv\modules\dnn\src\caffe\caffe_io.cpp:1126: error: (-2:Unspecified error) FAILED: fs.is_open(). Can't open "C:\Users\Admin\PycharmProjects\Facedetection_matched_ML\src\..\resources\detection_model\deploy.prototxt" in function 'cv::dnn::ReadProtoFromTextFile'

ERROR:root:Error: OpenCV(4.6.0) D:\a\opencv-python\opencv-python\opencv\modules\dnn\src\caffe\caffe_io.cpp:1126: error: (-2:Unspecified error) FAILED: fs.is_open(). Can't open "C:\Users\Admin\PycharmProjects\Facedetection_matched_ML\src\..\resources\detection_model\deploy.prototxt" in function 'cv::dnn::ReadProtoFromTextFile'

ERROR:root:Error: OpenCV(4.6.0) D:\a\opencv-python\opencv-python\opencv\modules\dnn\src\caffe\caffe_io.cpp:1126: error: (-2:Unspecified error) FAILED: fs.is_open(). Can't open "C:\Users\Admin\PycharmProjects\Facedetection_matched_ML\src\..\resources\detection_model\deploy.prototxt" in function 'cv::dnn::ReadProtoFromTextFile'

ERROR:root:Error: OpenCV(4.6.0) D:\a\opencv-python\opencv-python\opencv\modules\dnn\src\caffe\caffe_io.cpp:1126: error: (-2:Unspecified error) FAILED: fs.is_open(). Can't open "C:\Users\Admin\PycharmProjects\Facedetection_matched_ML\src\..\resources\detection_model\deploy.prototxt" in function 'cv::dnn::ReadProtoFromTextFile'

ERROR:root:Error: OpenCV(4.6.0) D:\a\opencv-python\opencv-python\opencv\modules\dnn\src\caffe\caffe_io.cpp:1126: error: (-2:Unspecified error) FAILED: fs.is_open(). Can't open "C:\Users\Admin\PycharmProjects\Facedetection_matched_ML\src\..\resources\detection_model\deploy.prototxt" in function 'cv::dnn::ReadProtoFromTextFile'

ERROR:root:Error: OpenCV(4.6.0) D:\a\opencv-python\opencv-python\opencv\modules\dnn\src\caffe\caffe_io.cpp:1126: error: (-2:Unspecified error) FAILED: fs.is_open(). Can't open "C:\Users\Admin\PycharmProjects\Facedetection_matched_ML\src\..\resources\detection_model\deploy.prototxt" in function 'cv::dnn::ReadProtoFromTextFile'

ERROR:root:Error: OpenCV(4.6.0) D:\a\opencv-python\opencv-python\opencv\modules\dnn\src\caffe\caffe_io.cpp:1126: error: (-2:Unspecified error) FAILED: fs.is_open(). Can't open "C:\Users\Admin\PycharmProjects\Facedetection_matched_ML\src\..\resources\detection_model\deploy.prototxt" in function 'cv::dnn::ReadProtoFromTextFile'

ERROR:root:Error: OpenCV(4.6.0) D:\a\opencv-python\opencv-python\opencv\modules\dnn\src\caffe\caffe_io.cpp:1126: error: (-2:Unspecified error) FAILED: fs.is_open(). Can't open "C:\Users\Admin\PycharmProjects\Facedetection_matched_ML\src\..\resources\detection_model\deploy.prototxt" in function 'cv::dnn::ReadProtoFromTextFile'

ERROR:root:Error: OpenCV(4.6.0) D:\a\opencv-python\opencv-python\opencv\modules\dnn\src\caffe\caffe_io.cpp:1126: error: (-2:Unspecified error) FAILED: fs.is_open(). Can't open "C:\Users\Admin\PycharmProjects\Facedetection_matched_ML\src\..\resources\detection_model\deploy.prototxt" in function 'cv::dnn::ReadProtoFromTextFile'

ERROR:root:Error: OpenCV(4.6.0) D:\a\opencv-python\opencv-python\opencv\modules\dnn\src\caffe\caffe_io.cpp:1126: error: (-2:Unspecified error) FAILED: fs.is_open(). Can't open "C:\Users\Admin\PycharmProjects\Facedetection_matched_ML\src\..\resources\detection_model\deploy.prototxt" in function 'cv::dnn::ReadProtoFromTextFile'

ERROR:root:Error: OpenCV(4.6.0) D:\a\opencv-python\opencv-python\opencv\modules\dnn\src\caffe\caffe_io.cpp:1126: error: (-2:Unspecified error) FAILED: fs.is_open(). Can't open "C:\Users\Admin\PycharmProjects\Facedetection_matched_ML\src\..\resources\detection_model\deploy.prototxt" in function 'cv::dnn::ReadProtoFromTextFile'

ERROR:root:Error: OpenCV(4.6.0) D:\a\opencv-python\opencv-python\opencv\modules\dnn\src\caffe\caffe_io.cpp:1126: error: (-2:Unspecified error) FAILED: fs.is_open(). Can't open "C:\Users\Admin\PycharmProjects\Facedetection_matched_ML\src\..\resources\detection_model\deploy.prototxt" in function 'cv::dnn::ReadProtoFromTextFile'

ERROR:root:Error: OpenCV(4.6.0) D:\a\opencv-python\opencv-python\opencv\modules\dnn\src\caffe\caffe_io.cpp:1126: error: (-2:Unspecified error) FAILED: fs.is_open(). Can't open "C:\Users\Admin\PycharmProjects\Facedetection_matched_ML\src\..\resources\detection_model\deploy.prototxt" in function 'cv::dnn::ReadProtoFromTextFile'

ERROR:root:Error: OpenCV(4.6.0) D:\a\opencv-python\opencv-python\opencv\modules\dnn\src\caffe\caffe_io.cpp:1126: error: (-2:Unspecified error) FAILED: fs.is_open(). Can't open "C:\Users\Admin\PycharmProjects\Facedetection_matched_ML\src\..\resources\detection_model\deploy.prototxt" in function 'cv::dnn::ReadProtoFromTextFile'

ERROR:root:Error: OpenCV(4.6.0) D:\a\opencv-python\opencv-python\opencv\modules\dnn\src\caffe\caffe_io.cpp:1126: error: (-2:Unspecified error) FAILED: fs.is_open(). Can't open "C:\Users\Admin\PycharmProjects\Facedetection_matched_ML\src\..\resources\detection_model\deploy.prototxt" in function 'cv::dnn::ReadProtoFromTextFile'

ERROR:root:Error: OpenCV(4.6.0) D:\a\opencv-python\opencv-python\opencv\modules\dnn\src\caffe\caffe_io.cpp:1126: error: (-2:Unspecified error) FAILED: fs.is_open(). Can't open "C:\Users\Admin\PycharmProjects\Facedetection_matched_ML\src\..\resources\detection_model\deploy.prototxt" in function 'cv::dnn::ReadProtoFromTextFile'

ERROR:root:Error: OpenCV(4.6.0) D:\a\opencv-python\opencv-python\opencv\modules\dnn\src\caffe\caffe_io.cpp:1126: error: (-2:Unspecified error) FAILED: fs.is_open(). Can't open "C:\Users\Admin\PycharmProjects\Facedetection_matched_ML\src\..\resources\detection_model\deploy.prototxt" in function 'cv::dnn::ReadProtoFromTextFile'

INFO:root:Name: captured_image_20231127120947
INFO:root:Name: captured_image_20231127120947
INFO:root:Name: captured_image_20231127120947
INFO:root:Name: captured_image_20231127120947
INFO:root:Name: captured_image_20231127120947
INFO:root:Name: captured_image_20231127120947
INFO:werkzeug: * Restarting with stat
WARNING:werkzeug: * Debugger is active!
INFO:werkzeug: * Debugger PIN: 801-066-297
INFO:root:Client connected
INFO:root:Name: captured_image_20231127120947
INFO:root:Name: captured_image_20231127120947
INFO:root:Name: captured_image_20231127120947
INFO:root:Name: captured_image_20231127120947
INFO:root:Name: captured_image_20231127120947
INFO:root:Name: captured_image_20231127120947
INFO:root:Name: captured_image_20231127120947
INFO:root:Name: captured_image_20231127120947
INFO:root:Name: captured_image_20231127120947
INFO:root:Name: captured_image_20231127120947
INFO:root:Name: captured_image_20231127120947
INFO:root:Name: captured_image_20231127120947
INFO:root:Name: captured_image_20231127120947
INFO:root:Name: captured_image_20231127120947
INFO:root:Name: captured_image_20231127120947
INFO:root:Name: captured_image_20231127120947
INFO:root:Name: captured_image_20231127120947
INFO:root:Name: captured_image_20231127120947
INFO:root:Name: captured_image_20231127120947
INFO:root:Name: captured_image_20231127120947
INFO:root:Name: captured_image_20231127120947
INFO:root:Name: captured_image_20231127120947
INFO:root:Name: captured_image_20231127120947
INFO:root:Name: captured_image_20231127120947
INFO:root:Name: captured_image_20231127120947
INFO:root:Name: captured_image_20231127120947
INFO:root:Name: captured_image_20231127120947
INFO:root:Name: captured_image_20231127120947
INFO:root:Name: captured_image_20231127120947
INFO:root:Name: captured_image_20231127120947
INFO:root:Name: captured_image_20231127120947
INFO:root:Name: captured_image_20231127120947
INFO:root:Name: captured_image_20231127120947
INFO:root:Name: captured_image_20231127120947
INFO:root:Name: captured_image_20231127120947
INFO:root:Name: captured_image_20231127120947
INFO:root:Client disconnected
INFO:root:Client connected
ERROR:root:frame does not detect a proper face
INFO:root:Name: captured_image_20231127120947
INFO:root:Name: captured_image_20231127120947
INFO:root:Name: captured_image_20231127120947
INFO:root:Name: captured_image_20231127120947
INFO:root:Name: captured_image_20231127120947
INFO:root:Name: captured_image_20231127120947
INFO:root:Name: captured_image_20231127120947
INFO:root:Name: captured_image_20231127120947
INFO:root:Client disconnected
INFO:werkzeug: * Restarting with stat
WARNING:werkzeug: * Debugger is active!
INFO:werkzeug: * Debugger PIN: 801-066-297
INFO:root:Client connected
ERROR:root:frame does not detect a proper face
INFO:root:Name: captured_image_20231127120947
INFO:root:Name: captured_image_20231127120947
INFO:root:Name: captured_image_20231127120947
INFO:root:Name: captured_image_20231127120947
INFO:root:Name: captured_image_20231127120947
INFO:root:Name: captured_image_20231127120947
INFO:root:Name: captured_image_20231127120947
INFO:root:Name: captured_image_20231127120947
INFO:root:Name: captured_image_20231127120947
INFO:root:Name: captured_image_20231127120947
INFO:root:Name: captured_image_20231127120947
INFO:root:Name: captured_image_20231127120947
INFO:root:Name: captured_image_20231127120947
INFO:root:Client disconnected
INFO:werkzeug: * Restarting with stat
WARNING:werkzeug: * Debugger is active!
INFO:werkzeug: * Debugger PIN: 801-066-297
INFO:werkzeug: * Restarting with stat
WARNING:werkzeug: * Debugger is active!
INFO:werkzeug: * Debugger PIN: 801-066-297
INFO:root:Client connected
INFO:root:Client connected
INFO:werkzeug: * Detected change in 'C:\\Users\\Admin\\PycharmProjects\\Facedetection_matched_ML\\spoofing_face_match_application.py', reloading
INFO:werkzeug: * Restarting with stat
INFO:werkzeug: * Restarting with stat
WARNING:werkzeug: * Debugger is active!
INFO:werkzeug: * Debugger PIN: 801-066-297
INFO:root:Client connected
INFO:root:Client connected
INFO:root:Client connected
INFO:root:Client disconnected
INFO:root:Client connected
ERROR:root:frame does not detect a proper face
INFO:root:Name: captured_image_20231127120947
INFO:root:Name: captured_image_20231127120947
INFO:root:Client disconnected
INFO:werkzeug: * Detected change in 'C:\\Users\\Admin\\PycharmProjects\\Facedetection_matched_ML\\spoofing_face_match_application.py', reloading
INFO:werkzeug: * Restarting with stat
WARNING:werkzeug: * Debugger is active!
INFO:werkzeug: * Debugger PIN: 801-066-297
INFO:root:Client connected
INFO:root:Client connected
INFO:werkzeug: * Detected change in 'C:\\Users\\Admin\\PycharmProjects\\Facedetection_matched_ML\\spoofing_face_match_application.py', reloading
INFO:werkzeug: * Restarting with stat
WARNING:werkzeug: * Debugger is active!
INFO:werkzeug: * Debugger PIN: 801-066-297
INFO:root:Client connected
INFO:root:Client connected
INFO:root:Client disconnected
INFO:root:Client disconnected
INFO:root:Client connected
ERROR:root:Error: 'NoneType' object has no attribute 'split'
INFO:werkzeug: * Detected change in 'C:\\Users\\Admin\\PycharmProjects\\Facedetection_matched_ML\\spoofing_face_match_application.py', reloading
INFO:werkzeug: * Restarting with stat
WARNING:werkzeug: * Debugger is active!
INFO:werkzeug: * Debugger PIN: 801-066-297
INFO:root:Client connected
ERROR:root:Error: 'NoneType' object has no attribute 'split'
INFO:root:Client disconnected
INFO:root:Client connected
ERROR:root:Error: 'NoneType' object has no attribute 'split'
INFO:werkzeug: * Detected change in 'C:\\Users\\Admin\\PycharmProjects\\Facedetection_matched_ML\\spoofing_face_match_application.py', reloading
INFO:werkzeug: * Restarting with stat
WARNING:werkzeug: * Debugger is active!
INFO:werkzeug: * Debugger PIN: 801-066-297
INFO:root:Client connected
INFO:root:Client disconnected
INFO:root:Client connected
ERROR:root:Error: 'NoneType' object has no attribute 'split'
INFO:werkzeug: * Detected change in 'C:\\Users\\Admin\\PycharmProjects\\Facedetection_matched_ML\\spoofing_face_match_application.py', reloading
INFO:werkzeug: * Restarting with stat
INFO:werkzeug: * Restarting with stat
WARNING:werkzeug: * Debugger is active!
INFO:werkzeug: * Debugger PIN: 801-066-297
INFO:root:Client connected
ERROR:root:Error: 'NoneType' object has no attribute 'split'
INFO:werkzeug: * Detected change in 'C:\\Users\\Admin\\PycharmProjects\\Facedetection_matched_ML\\spoofing_face_match_application.py', reloading
INFO:werkzeug: * Restarting with stat
WARNING:werkzeug: * Debugger is active!
INFO:werkzeug: * Debugger PIN: 801-066-297
INFO:root:Client connected
INFO:root:Client disconnected
INFO:root:Client connected
ERROR:root:Error: list index out of range
INFO:root:Client disconnected
INFO:root:Client connected
ERROR:root:Error: list index out of range
INFO:root:Client connected
ERROR:root:Error: list index out of range
INFO:root:Client connected
ERROR:root:Error: list index out of range
INFO:root:Client disconnected
INFO:root:Client disconnected
INFO:root:Client disconnected
INFO:root:Client connected
ERROR:root:Error: a bytes-like object is required, not 'str'
INFO:root:Client connected
ERROR:root:Error: a bytes-like object is required, not 'str'
INFO:root:Client connected
ERROR:root:Error: a bytes-like object is required, not 'str'
INFO:root:Client connected
ERROR:root:Error: a bytes-like object is required, not 'str'
INFO:root:Client connected
ERROR:root:Error: a bytes-like object is required, not 'str'
INFO:root:Client connected
ERROR:root:Error: a bytes-like object is required, not 'str'
INFO:root:Client connected
ERROR:root:Error: a bytes-like object is required, not 'str'
INFO:root:Client connected
ERROR:root:Error: a bytes-like object is required, not 'str'
INFO:root:Client connected
ERROR:root:Error: a bytes-like object is required, not 'str'
INFO:root:Client connected
ERROR:root:Error: a bytes-like object is required, not 'str'
INFO:root:Client connected
ERROR:root:Error: d, a bytes-like object is requirenot 'str'
INFO:werkzeug: * Restarting with stat
WARNING:werkzeug: * Debugger is active!
INFO:werkzeug: * Debugger PIN: 801-066-297
INFO:root:Client connected
ERROR:root:frame does not detect a proper face
INFO:root:Name: captured_image_20231127120947
INFO:root:Name: captured_image_20231127120947
INFO:root:Name: captured_image_20231127120947
INFO:root:Name: captured_image_20231127120947
INFO:root:Name: captured_image_20231127120947
ERROR:root:frame does not detect a proper face
INFO:root:Name: 1702453152312
INFO:root:Name: 1702453152312
INFO:root:Name: 1702453152312
INFO:root:Name: ujjawal
INFO:root:Name: 1702453152312
INFO:root:Name: captured_image_20231127120947
INFO:root:Name: captured_image_20231127120947
INFO:root:Name: captured_image_20231127120947
INFO:root:Name: captured_image_20231127120947
INFO:root:Name: captured_image_20231127120947
INFO:root:Name: VISHNU K
INFO:werkzeug: * Restarting with stat
WARNING:werkzeug: * Debugger is active!
INFO:werkzeug: * Debugger PIN: 801-066-297
INFO:root:Client connected
ERROR:root:frame does not detect a proper face
INFO:root:Name: captured_image_20231127120947
INFO:root:Name: captured_image_20231127120947
INFO:root:Name: captured_image_20231127120947
INFO:root:Name: captured_image_20231127120947
INFO:root:Name: captured_image_20231127120947
INFO:root:Name: ujjawal
INFO:root:Name: captured_image_20231127120947
INFO:root:Name: captured_image_20231127120947
INFO:werkzeug: * Restarting with stat
WARNING:werkzeug: * Debugger is active!
INFO:werkzeug: * Debugger PIN: 801-066-297
INFO:root:Client connected
INFO:root:Name: captured_image_20231127120947
INFO:root:Name: captured_image_20231127120947
INFO:root:Name: captured_image_20231127120947
INFO:root:Name: captured_image_20231127120947
INFO:root:Name: 1702453152312
INFO:root:Name: 1702453152312
INFO:root:Name: captured_image_20231127120947
INFO:root:Name: captured_image_20231127120947
INFO:root:Name: 1702453152312
INFO:root:Name: 1702453152312
INFO:root:Name: captured_image_20231127120947
INFO:root:Name: captured_image_20231127120947
INFO:root:Name: ujjawal
INFO:root:Name: 1702453152312
INFO:werkzeug: * Restarting with stat
WARNING:werkzeug: * Debugger is active!
INFO:werkzeug: * Debugger PIN: 801-066-297
INFO:root:Client connected
INFO:root:Client connected
ERROR:root:frame does not detect a proper face
ERROR:root:frame does not detect a proper face
ERROR:root:frame does not detect a proper face
INFO:werkzeug: * Detected change in 'C:\\Users\\Admin\\PycharmProjects\\Facedetection_matched_ML\\spoofing_face_match_application.py', reloading
INFO:werkzeug: * Restarting with stat
WARNING:werkzeug: * Debugger is active!
INFO:werkzeug: * Debugger PIN: 801-066-297
INFO:root:Client connected
INFO:root:Client connected
ERROR:root:frame does not detect a proper face
ERROR:root:frame does not detect a proper face
ERROR:root:frame does not detect a proper face
ERROR:root:frame does not detect a proper face
ERROR:root:frame does not detect a proper face
ERROR:root:frame does not detect a proper face
INFO:werkzeug: * Detected change in 'C:\\Users\\Admin\\PycharmProjects\\Facedetection_matched_ML\\spoofing_face_match_application.py', reloading
INFO:werkzeug: * Restarting with stat
INFO:werkzeug: * Restarting with stat
WARNING:werkzeug: * Debugger is active!
INFO:werkzeug: * Debugger PIN: 801-066-297
INFO:root:Client connected
ERROR:root:frame does not detect a proper face
INFO:root:Client connected
ERROR:root:frame does not detect a proper face
ERROR:root:frame does not detect a proper face
INFO:werkzeug: * Detected change in 'C:\\Users\\Admin\\PycharmProjects\\Facedetection_matched_ML\\spoofing_face_match_application.py', reloading
INFO:werkzeug: * Restarting with stat
INFO:werkzeug: * Restarting with stat
WARNING:werkzeug: * Debugger is active!
INFO:werkzeug: * Debugger PIN: 801-066-297
INFO:root:Client connected
INFO:root:Client connected
ERROR:root:frame does not detect a proper face
ERROR:root:frame does not detect a proper face
ERROR:root:frame does not detect a proper face
ERROR:root:frame does not detect a proper face
ERROR:root:frame does not detect a proper face
INFO:root:Client disconnected
INFO:root:Client connected
ERROR:root:frame does not detect a proper face
INFO:werkzeug: * Detected change in 'C:\\Users\\Admin\\PycharmProjects\\Facedetection_matched_ML\\spoofing_face_match_application.py', reloading
INFO:werkzeug: * Restarting with stat
INFO:werkzeug: * Restarting with stat
WARNING:werkzeug: * Debugger is active!
INFO:werkzeug: * Debugger PIN: 801-066-297
INFO:root:Client connected
INFO:root:Client connected
INFO:root:Client disconnected
INFO:root:Client connected
INFO:root:Client disconnected
ERROR:root:frame does not detect a proper face
INFO:werkzeug: * Detected change in 'C:\\Users\\Admin\\PycharmProjects\\Facedetection_matched_ML\\spoofing_face_match_application.py', reloading
INFO:werkzeug: * Restarting with stat
INFO:werkzeug: * Restarting with stat
WARNING:werkzeug: * Debugger is active!
INFO:werkzeug: * Debugger PIN: 801-066-297
INFO:root:Client connected
ERROR:root:frame does not detect a proper face
INFO:werkzeug: * Restarting with stat
WARNING:werkzeug: * Debugger is active!
INFO:werkzeug: * Debugger PIN: 801-066-297
INFO:root:User 6V503D07DEO7sKGZAAAB connected
INFO:werkzeug: * Detected change in 'C:\\Users\\Admin\\PycharmProjects\\Facedetection_matched_ML\\app.py', reloading
INFO:werkzeug: * Restarting with stat
INFO:werkzeug: * Restarting with stat
WARNING:werkzeug: * Debugger is active!
INFO:werkzeug: * Debugger PIN: 801-066-297
INFO:werkzeug: * Detected change in 'C:\\Users\\Admin\\PycharmProjects\\Facedetection_matched_ML\\app.py', reloading
INFO:werkzeug: * Restarting with stat
WARNING:werkzeug: * Debugger is active!
INFO:werkzeug: * Debugger PIN: 801-066-297
INFO:root:User KMdJ-CQx3gJ2aPn9AAAB connected
INFO:root:Name: dimpal
INFO:root:Name: dimpal
INFO:root:Name: dimpal
INFO:root:Name: dimpal
INFO:root:Name: dimpal
INFO:root:Name: dimpal
INFO:root:Name: dimpal
INFO:root:Name: dimpal
ERROR:root:frame does not detect a proper face
INFO:root:Name: dimpal
INFO:root:Name: dimpal
INFO:root:Name: dimpal
INFO:root:Name: dimpal
INFO:root:Name: dimpal
INFO:root:Name: dimpal
INFO:root:Name: dimpal
INFO:root:Name: dimpal
INFO:root:Name: dimpal
ERROR:root:frame does not detect a proper face
INFO:root:Name: dimpal
INFO:root:User KMdJ-CQx3gJ2aPn9AAAB disconnected
INFO:root:User upHkrAisoPF8LzS-AAAD connected
ERROR:root:frame does not detect a proper face
INFO:root:Name: dimpal
INFO:root:Name: dimpal
INFO:root:Name: dimpal
INFO:root:Name: dimpal
INFO:root:Name: dimpal
INFO:root:Name: dimpal
INFO:root:Name: dimpal
INFO:root:Name: dimpal
INFO:root:Name: dimpal
INFO:werkzeug: * Restarting with stat
WARNING:werkzeug: * Debugger is active!
INFO:werkzeug: * Debugger PIN: 801-066-297
INFO:root:User tZnSa3Md2mS8IBQbAAAB connected
INFO:root:Name: dimpal
INFO:root:Name: dimpal
INFO:root:Name: dimpal
INFO:root:Name: dimpal
INFO:root:Name: dimpal
INFO:root:Name: dimpal
INFO:root:Name: dimpal
INFO:root:Name: dimpal
INFO:root:Name: dimpal
INFO:root:Name: dimpal
INFO:root:Name: dimpal
INFO:root:Name: dimpal
INFO:root:Name: dimpal
INFO:root:Name: dimpal
INFO:root:Name: dimpal
INFO:root:Name: dimpal
INFO:root:Name: dimpal
INFO:root:Name: dimpal
INFO:root:Name: dimpal
INFO:root:Name: dimpal
INFO:root:Name: dimpal
INFO:root:Name: dimpal
INFO:root:Name: dimpal
ERROR:root:frame does not detect a proper face
INFO:root:Name: dimpal
INFO:root:Name: dimpal
INFO:root:Name: dimpal
INFO:root:Name: dimpal
INFO:root:Name: dimpal
INFO:root:Name: dimpal
INFO:root:Name: dimpal
INFO:root:Name: dimpal
INFO:root:Name: dimpal
INFO:root:Name: dimpal
INFO:root:Name: dimpal
INFO:root:Name: dimpal
INFO:root:Name: dimpal
INFO:root:Name: dimpal
INFO:root:Name: dimpal
INFO:root:User tZnSa3Md2mS8IBQbAAAB disconnected
INFO:root:User 8uM9T23BrzwCCOT6AAAD connected
ERROR:root:frame does not detect a proper face
INFO:root:Name: dimpal
INFO:root:Name: dimpal
INFO:root:Name: dimpal
INFO:root:Name: dimpal
INFO:root:Name: dimpal
INFO:root:Name: dimpal
INFO:root:Name: dimpal
INFO:root:Name: dimpal
INFO:root:Name: dimpal
INFO:root:Name: dimpal
INFO:root:Name: dimpal
INFO:root:Name: dimpal
INFO:root:Name: dimpal
INFO:root:Name: dimpal
INFO:root:Name: dimpal
INFO:root:Name: dimpal
INFO:root:Name: dimpal
INFO:root:Name: dimpal
INFO:root:Name: dimpal
INFO:root:Name: dimpal
INFO:root:Name: dimpal
INFO:root:Name: dimpal
ERROR:root:frame does not detect a proper face
ERROR:root:frame does not detect a proper face
INFO:root:Name: dimpal
INFO:werkzeug: * Restarting with stat
WARNING:werkzeug: * Debugger is active!
INFO:werkzeug: * Debugger PIN: 801-066-297
INFO:root:User ApjLTfFwZicrMn_RAAAB connected
ERROR:root:Error: Invalid data format
INFO:root:Name: dimpal
INFO:root:Name: dimpal
INFO:root:Name: dimpal
INFO:root:Name: dimpal
INFO:root:Name: dimpal
INFO:root:Name: dimpal
INFO:root:Name: dimpal
INFO:root:Name: dimpal
INFO:root:Name: dimpal
INFO:root:Name: dimpal
INFO:root:Name: dimpal
INFO:root:Name: dimpal
INFO:root:Name: dimpal
INFO:root:Name: dimpal
INFO:root:Name: dimpal
INFO:root:Name: dimpal
INFO:root:Name: dimpal
INFO:root:Name: dimpal
INFO:root:Name: dimpal
INFO:root:Name: dimpal
INFO:root:Name: dimpal
INFO:root:Name: dimpal
INFO:root:Name: dimpal
INFO:root:Name: dimpal
INFO:root:Name: dimpal
INFO:root:Name: dimpal
INFO:root:Name: dimpal
INFO:root:Name: dimpal
INFO:root:Name: dimpal
INFO:root:Name: dimpal
INFO:root:Name: dimpal
INFO:werkzeug: * Detected change in 'C:\\Users\\Admin\\PycharmProjects\\Facedetection_matched_ML\\app.py', reloading
INFO:werkzeug: * Restarting with stat
WARNING:werkzeug: * Debugger is active!
INFO:werkzeug: * Debugger PIN: 801-066-297
INFO:root:User sl_PEm-OuLQeH-dMAAAB connected
INFO:werkzeug: * Restarting with stat
WARNING:werkzeug: * Debugger is active!
INFO:werkzeug: * Debugger PIN: 801-066-297
INFO:root:Client connected
INFO:werkzeug: * Detected change in 'C:\\Users\\Admin\\PycharmProjects\\Facedetection_matched_ML\\spoofing_face_match_application.py', reloading
INFO:werkzeug: * Restarting with stat
WARNING:werkzeug: * Debugger is active!
INFO:werkzeug: * Debugger PIN: 801-066-297
INFO:root:Client connected
INFO:root:Name: dimpal
INFO:root:Name: dimpal
INFO:root:Name: dimpal
INFO:root:Name: dimpal
INFO:root:Name: dimpal
INFO:root:Name: dimpal
INFO:root:Name: dimpal
INFO:werkzeug: * Restarting with stat
INFO:werkzeug: * Restarting with stat
WARNING:werkzeug: * Debugger is active!
INFO:werkzeug: * Debugger PIN: 801-066-297
INFO:werkzeug: * Detected change in 'C:\\Users\\Admin\\PycharmProjects\\Facedetection_matched_ML\\app.py', reloading
INFO:werkzeug: * Restarting with stat
INFO:werkzeug: * Restarting with stat
WARNING:werkzeug: * Debugger is active!
INFO:werkzeug: * Debugger PIN: 801-066-297
INFO:werkzeug: * Restarting with stat
WARNING:werkzeug: * Debugger is active!
INFO:werkzeug: * Debugger PIN: 801-066-297
INFO:werkzeug: * Restarting with stat
WARNING:werkzeug: * Debugger is active!
INFO:werkzeug: * Debugger PIN: 801-066-297
INFO:root:User FDtmpbW20kbHgfiFAAAB connected
ERROR:root:Error: Invalid data format
INFO:root:Name: dimpal
INFO:root:Name: dimpal
INFO:root:Name: dimpal
INFO:root:Name: dimpal
INFO:root:Name: dimpal
INFO:root:Name: dimpal
INFO:root:Name: dimpal
INFO:root:Name: dimpal
INFO:root:Name: dimpal
INFO:root:Name: dimpal
INFO:root:Name: dimpal
INFO:root:Name: dimpal
INFO:root:Name: dimpal
INFO:root:Name: dimpal
INFO:root:Name: dimpal
INFO:root:Name: dimpal
INFO:root:Name: dimpal
INFO:root:Name: dimpal
INFO:root:Name: dimpal
INFO:root:Name: dimpal
INFO:root:Name: dimpal
INFO:root:Name: dimpal
INFO:root:Name: dimpal
INFO:root:Name: dimpal
INFO:root:Name: dimpal
INFO:root:Name: dimpal
INFO:root:Name: dimpal
INFO:root:Name: dimpal
INFO:root:Name: dimpal
INFO:root:Name: dimpal
INFO:root:Name: dimpal
INFO:root:Name: dimpal
INFO:werkzeug: * Restarting with stat
WARNING:werkzeug: * Debugger is active!
INFO:werkzeug: * Debugger PIN: 801-066-297
INFO:root:User zUPl-eAmC4MlQS2vAAAB connected
ERROR:root:Error: Invalid data format
INFO:root:Name: dimpal
INFO:root:Name: dimpal
INFO:root:Name: dimpal
INFO:root:Name: dimpal
INFO:root:Name: dimpal
INFO:root:Name: dimpal
INFO:root:Name: dimpal
INFO:root:Name: dimpal
INFO:root:Name: dimpal
INFO:root:Name: dimpal
INFO:root:Name: dimpal
INFO:root:Name: dimpal
INFO:werkzeug: * Restarting with stat
WARNING:werkzeug: * Debugger is active!
INFO:werkzeug: * Debugger PIN: 801-066-297
INFO:root:User uvOp8uIZbIApShTJAAAB connected
ERROR:root:Error: Invalid data format
INFO:root:Name: dimpal
INFO:root:Name: dimpal
INFO:root:Name: dimpal
INFO:root:Name: dimpal
INFO:root:Name: dimpal
INFO:root:Name: dimpal
INFO:root:Name: dimpal
INFO:root:Name: dimpal
INFO:root:Name: dimpal
INFO:root:Name: dimpal
INFO:root:Name: dimpal
INFO:root:Name: dimpal
INFO:root:User uvOp8uIZbIApShTJAAAB disconnected
INFO:werkzeug: * Restarting with stat
WARNING:werkzeug: * Debugger is active!
INFO:werkzeug: * Debugger PIN: 801-066-297
INFO:root:Client connected
ERROR:root:Error: Invalid data format
INFO:root:Name: dimpal
INFO:root:Name: dimpal
INFO:root:Name: dimpal
INFO:root:Name: dimpal
INFO:root:Name: dimpal
INFO:root:Name: dimpal
INFO:root:Name: dimpal
INFO:root:Name: dimpal
INFO:root:Name: dimpal
INFO:root:Name: dimpal
INFO:root:Name: dimpal
INFO:root:Name: dimpal
INFO:root:Name: dimpal
INFO:root:Name: dimpal
INFO:root:Name: dimpal
INFO:root:Name: dimpal
INFO:root:Name: dimpal
INFO:root:Client disconnected
INFO:werkzeug: * Restarting with stat
WARNING:werkzeug: * Debugger is active!
INFO:werkzeug: * Debugger PIN: 801-066-297
INFO:root:Client connected
ERROR:root:Error: Invalid data format
INFO:root:Name: dimpal
INFO:root:Name: dimpal
INFO:root:Name: dimpal
INFO:root:Name: dimpal
INFO:root:Name: dimpal
INFO:root:Name: dimpal
INFO:root:Name: dimpal
INFO:root:Name: dimpal
INFO:root:Name: dimpal
INFO:root:Name: dimpal
INFO:root:Name: dimpal
INFO:root:Name: dimpal
INFO:root:Name: dimpal
INFO:root:Name: dimpal
INFO:root:Name: dimpal
INFO:root:Name: dimpal
INFO:root:Name: dimpal
INFO:root:Name: dimpal
INFO:werkzeug: * Detected change in 'C:\\Users\\Admin\\PycharmProjects\\Facedetection_matched_ML\\spoofing_face_match_application.py', reloading
INFO:werkzeug: * Restarting with stat
WARNING:werkzeug: * Debugger is active!
INFO:werkzeug: * Debugger PIN: 801-066-297
INFO:root:Client connected
ERROR:root:Error: Invalid data format
INFO:root:Name: dimpal
INFO:root:Name: dimpal
INFO:root:Name: dimpal
INFO:root:Name: dimpal
INFO:root:Name: dimpal
INFO:root:Name: dimpal
INFO:root:Name: dimpal
INFO:root:Name: dimpal
INFO:root:Name: dimpal
INFO:root:Name: dimpal
INFO:root:Name: dimpal
INFO:root:Name: dimpal
INFO:root:Name: dimpal
INFO:root:Name: dimpal
INFO:root:Name: dimpal
INFO:root:Name: dimpal
INFO:root:Name: dimpal
INFO:root:Name: dimpal
INFO:root:Name: dimpal
INFO:root:Client disconnected
INFO:werkzeug: * Restarting with stat
WARNING:werkzeug: * Debugger is active!
INFO:werkzeug: * Debugger PIN: 801-066-297
INFO:root:Client connected
ERROR:root:Error: Invalid data format
ERROR:root:Error: name 'image_database' is not defined
ERROR:root:Error: name 'image_database' is not defined
ERROR:root:Error: name 'image_database' is not defined
ERROR:root:Error: name 'image_database' is not defined
ERROR:root:Error: name 'image_database' is not defined
ERROR:root:Error: name 'image_database' is not defined
ERROR:root:Error: name 'image_database' is not defined
ERROR:root:Error: name 'image_database' is not defined
ERROR:root:Error: name 'image_database' is not defined
ERROR:root:Error: name 'image_database' is not defined
ERROR:root:Error: name 'image_database' is not defined
ERROR:root:Error: name 'image_database' is not defined
ERROR:root:Error: name 'image_database' is not defined
ERROR:root:Error: name 'image_database' is not defined
ERROR:root:Error: name 'image_database' is not defined
ERROR:root:Error: name 'image_database' is not defined
ERROR:root:Error: name 'image_database' is not defined
ERROR:root:Error: name 'image_database' is not defined
ERROR:root:Error: name 'image_database' is not defined
ERROR:root:Error: name 'image_database' is not defined
ERROR:root:Error: name 'image_database' is not defined
ERROR:root:Error: name 'image_database' is not defined
ERROR:root:Error: name 'image_database' is not defined
INFO:werkzeug: * Restarting with stat
WARNING:werkzeug: * Debugger is active!
INFO:werkzeug: * Debugger PIN: 801-066-297
INFO:root:Client connected
ERROR:root:Error: Invalid data format
INFO:root:Client disconnected
INFO:werkzeug: * Detected change in 'C:\\Users\\Admin\\PycharmProjects\\Facedetection_matched_ML\\spoofing_face_match_application.py', reloading
INFO:werkzeug: * Restarting with stat
WARNING:werkzeug: * Debugger is active!
INFO:werkzeug: * Debugger PIN: 801-066-297
INFO:werkzeug: * Detected change in 'C:\\Users\\Admin\\PycharmProjects\\Facedetection_matched_ML\\spoofing_face_match_application.py', reloading
INFO:werkzeug: * Restarting with stat
INFO:werkzeug: * Restarting with stat
WARNING:werkzeug: * Debugger is active!
INFO:werkzeug: * Debugger PIN: 801-066-297
INFO:werkzeug: * Detected change in 'C:\\Users\\Admin\\PycharmProjects\\Facedetection_matched_ML\\spoofing_face_match_application.py', reloading
INFO:werkzeug: * Restarting with stat
WARNING:werkzeug: * Debugger is active!
INFO:werkzeug: * Debugger PIN: 801-066-297
INFO:root:Client connected
ERROR:root:Error: Invalid data format
INFO:root:Name: dimpal
INFO:root:Name: dimpal
INFO:root:Name: dimpal
INFO:root:Name: dimpal
INFO:root:Name: dimpal
INFO:root:Name: dimpal
INFO:root:Name: dimpal
ERROR:root:frame does not detect a proper face
ERROR:root:frame does not detect a proper face
INFO:root:Name: dimpal
INFO:root:Name: dimpal
INFO:werkzeug: * Restarting with stat
WARNING:werkzeug: * Debugger is active!
INFO:werkzeug: * Debugger PIN: 801-066-297
INFO:root:Client connected
ERROR:root:Error: Invalid data format
INFO:root:Name: dimpal
INFO:root:Name: dimpal
INFO:root:Name: dimpal
INFO:root:Name: dimpal
INFO:root:Name: dimpal
INFO:root:Name: dimpal
INFO:root:Name: dimpal
INFO:root:Name: dimpal
INFO:root:Name: dimpal
INFO:root:Name: dimpal
INFO:root:Client disconnected
INFO:werkzeug: * Detected change in 'C:\\Users\\Admin\\PycharmProjects\\Facedetection_matched_ML\\spoofing_face_match_application.py', reloading
INFO:werkzeug: * Restarting with stat
WARNING:werkzeug: * Debugger is active!
INFO:werkzeug: * Debugger PIN: 801-066-297
INFO:werkzeug: * Detected change in 'C:\\Users\\Admin\\PycharmProjects\\Facedetection_matched_ML\\spoofing_face_match_application.py', reloading
INFO:werkzeug: * Restarting with stat
WARNING:werkzeug: * Debugger is active!
INFO:werkzeug: * Debugger PIN: 801-066-297
INFO:werkzeug: * Detected change in 'C:\\Users\\Admin\\PycharmProjects\\Facedetection_matched_ML\\app.py', reloading
INFO:werkzeug: * Restarting with stat
WARNING:werkzeug: * Debugger is active!
INFO:werkzeug: * Debugger PIN: 801-066-297
INFO:werkzeug: * Detected change in 'C:\\Users\\Admin\\PycharmProjects\\Facedetection_matched_ML\\app.py', reloading
INFO:werkzeug: * Restarting with stat
WARNING:werkzeug: * Debugger is active!
INFO:werkzeug: * Debugger PIN: 801-066-297
INFO:werkzeug: * Restarting with stat
WARNING:werkzeug: * Debugger is active!
INFO:werkzeug: * Debugger PIN: 801-066-297
INFO:root:Client connected
ERROR:root:Error: Invalid data format
INFO:root:Name: dimpal
INFO:root:Name: dimpal
INFO:root:Name: dimpal
INFO:root:Name: dimpal
INFO:root:Name: dimpal
INFO:root:Name: dimpal
INFO:root:Name: dimpal
INFO:root:Name: dimpal
INFO:root:Name: dimpal
INFO:root:Name: dimpal
INFO:root:Name: dimpal
INFO:root:Name: dimpal
INFO:root:Name: dimpal
INFO:root:Name: dimpal
INFO:root:Client disconnected
INFO:werkzeug: * Restarting with stat
WARNING:werkzeug: * Debugger is active!
INFO:werkzeug: * Debugger PIN: 801-066-297
INFO:root:User SLJ9fu8CTq0zy363AAAB connected
ERROR:root:Error: Invalid data format
INFO:root:Name: dimpal
INFO:root:Name: dimpal
INFO:root:Name: dimpal
INFO:root:Name: dimpal
INFO:root:Name: dimpal
INFO:root:Name: dimpal
INFO:root:Name: dimpal
INFO:root:User SLJ9fu8CTq0zy363AAAB disconnected
